<?xml version="1.0" encoding="UTF-8"?>
<!-- Generated by org.testng.reporters.JUnitReportReporter -->
<testsuite skipped="5" hostname="DESKTOP-BGOVQ9A" name="demo.TestNGRetryFailedDemo" tests="8" failures="1" timestamp="2021-08-24T10:43:33 MST" time="0.063" errors="0">
  <testcase name="test3" time="0.012" classname="demo.TestNGRetryFailedDemo">
    <skipped/>
  </testcase> <!-- test3 -->
  <system-out/>
  <testcase name="test3" time="0.007" classname="demo.TestNGRetryFailedDemo">
    <skipped/>
  </testcase> <!-- test3 -->
  <system-out/>
  <testcase name="test3" time="0.005" classname="demo.TestNGRetryFailedDemo">
    <skipped/>
  </testcase> <!-- test3 -->
  <system-out/>
  <testcase name="test2" time="0.009" classname="demo.TestNGRetryFailedDemo"/>
  <system-out/>
  <testcase name="test3" time="0.003" classname="demo.TestNGRetryFailedDemo">
    <skipped/>
  </testcase> <!-- test3 -->
  <system-out/>
  <testcase name="test3" time="0.004" classname="demo.TestNGRetryFailedDemo">
    <failure type="java.lang.AssertionError" message="expected [true] but found [false]">
      <![CDATA[java.lang.AssertionError: expected [true] but found [false]
at org.testng.Assert.fail(Assert.java:99)
at org.testng.Assert.failNotEquals(Assert.java:1037)
at org.testng.Assert.assertTrue(Assert.java:45)
at org.testng.Assert.assertTrue(Assert.java:55)
at demo.TestNGRetryFailedDemo.test3(TestNGRetryFailedDemo.java:24)
at sun.reflect.NativeMethodAccessorImpl.invoke0(Native Method)
at sun.reflect.NativeMethodAccessorImpl.invoke(NativeMethodAccessorImpl.java:62)
at sun.reflect.DelegatingMethodAccessorImpl.invoke(DelegatingMethodAccessorImpl.java:43)
at java.lang.reflect.Method.invoke(Method.java:498)
at org.testng.internal.MethodInvocationHelper.invokeMethod(MethodInvocationHelper.java:133)
at org.testng.internal.TestInvoker.invokeMethod(TestInvoker.java:598)
at org.testng.internal.TestInvoker.retryFailed(TestInvoker.java:213)
at org.testng.internal.MethodRunner.runInSequence(MethodRunner.java:58)
at org.testng.internal.TestInvoker$MethodInvocationAgent.invoke(TestInvoker.java:824)
at org.testng.internal.TestInvoker.invokeTestMethods(TestInvoker.java:146)
at org.testng.internal.TestMethodWorker.invokeTestMethods(TestMethodWorker.java:146)
at org.testng.internal.TestMethodWorker.run(TestMethodWorker.java:128)
at java.util.ArrayList.forEach(ArrayList.java:1259)
at org.testng.TestRunner.privateRun(TestRunner.java:794)
at org.testng.TestRunner.run(TestRunner.java:596)
at org.testng.SuiteRunner.runTest(SuiteRunner.java:377)
at org.testng.SuiteRunner.runSequentially(SuiteRunner.java:371)
at org.testng.SuiteRunner.privateRun(SuiteRunner.java:332)
at org.testng.SuiteRunner.run(SuiteRunner.java:276)
at org.testng.SuiteRunnerWorker.runSuite(SuiteRunnerWorker.java:53)
at org.testng.SuiteRunnerWorker.run(SuiteRunnerWorker.java:96)
at org.testng.TestNG.runSuitesSequentially(TestNG.java:1212)
at org.testng.TestNG.runSuitesLocally(TestNG.java:1134)
at org.testng.TestNG.runSuites(TestNG.java:1063)
at org.testng.TestNG.run(TestNG.java:1031)
at org.testng.remote.AbstractRemoteTestNG.run(AbstractRemoteTestNG.java:115)
at org.testng.remote.RemoteTestNG.initAndRun(RemoteTestNG.java:251)
at org.testng.remote.RemoteTestNG.main(RemoteTestNG.java:77)
]]>
    </failure>
  </testcase> <!-- test3 -->
  <system-out/>
  <testcase name="test3" time="0.007" classname="demo.TestNGRetryFailedDemo">
    <skipped/>
  </testcase> <!-- test3 -->
  <system-out/>
  <testcase name="test1" time="0.016" classname="demo.TestNGRetryFailedDemo"/>
  <system-out/>
</testsuite> <!-- demo.TestNGRetryFailedDemo -->
